<sdf version='1.7'>
  <world name='default'>
    <plugin name="hello_world" filename="libhello_world.dylib"/>
    <light name='sun' type='directional'>
      <cast_shadows>1</cast_shadows>
      <pose>0 0 10 0 -0 0</pose>
      <diffuse>0.8 0.8 0.8 1</diffuse>
      <specular>0.2 0.2 0.2 1</specular>
      <attenuation>
        <range>1000</range>
        <constant>0.9</constant>
        <linear>0.01</linear>
        <quadratic>0.001</quadratic>
      </attenuation>
      <direction>-0.5 0.1 -0.9</direction>
      <spot>
        <inner_angle>0</inner_angle>
        <outer_angle>0</outer_angle>
        <falloff>0</falloff>
      </spot>
    </light>
    <model name='ground_plane'>
      <static>1</static>
      <link name='link'>
        <collision name='collision'>
          <geometry>
            <plane>
              <normal>0 0 1</normal>
              <size>100 100</size>
            </plane>
          </geometry>
          <surface>
            <contact>
              <collide_bitmask>65535</collide_bitmask>
              <ode/>
            </contact>
            <friction>
              <ode>
                <mu>100</mu>
                <mu2>50</mu2>
              </ode>
              <torsional>
                <ode/>
              </torsional>
            </friction>
            <bounce/>
          </surface>
          <max_contacts>10</max_contacts>
        </collision>
        <visual name='visual'>
          <cast_shadows>0</cast_shadows>
          <geometry>
            <plane>
              <normal>0 0 1</normal>
              <size>100 100</size>
            </plane>
          </geometry>
        </visual>
        <self_collide>0</self_collide>
        <enable_wind>0</enable_wind>
        <kinematic>0</kinematic>
      </link>
    </model>
    <gravity>0 0 -9.8</gravity>
    <magnetic_field>6e-06 2.3e-05 -4.2e-05</magnetic_field>
    <atmosphere type='adiabatic'/>
    <physics type='ode'>
      <max_step_size>0.001</max_step_size>
      <real_time_factor>1</real_time_factor>
      <real_time_update_rate>1000</real_time_update_rate>
    </physics>
    <scene>
      <ambient>0.4 0.4 0.4 1</ambient>
      <background>0.7 0.7 0.7 1</background>
      <shadows>1</shadows>
    </scene>
    <audio>
      <device>default</device>
    </audio>
    <wind/>
    <spherical_coordinates>
      <surface_model>EARTH_WGS84</surface_model>
      <latitude_deg>0</latitude_deg>
      <longitude_deg>0</longitude_deg>
      <elevation>0</elevation>
      <heading_deg>0</heading_deg>
    </spherical_coordinates>




    <model name='robot'>
      <plugin name='diff_drive' filename="libdiff_drive.dylib"/>
      <pose>0 0 0.325 0 -0 0</pose>
      <link name='chassis'>
        <pose>-0.151427 -0 0.175 0 -0 0</pose>
        <inertial>
          <mass>1.14395</mass>
          <inertia>
            <ixx>0.126164</ixx>
            <ixy>0</ixy>
            <ixz>0</ixz>
            <iyy>0.416519</iyy>
            <iyz>0</iyz>
            <izz>0.481014</izz>
          </inertia>
          <pose>0 0 0 0 -0 0</pose>
        </inertial>
        <self_collide>0</self_collide>
        <visual name='visual'>
          <pose>0 0 0 0 -0 0</pose>
          <geometry>
            <box>
              <size>2.01142 1 0.568726</size>
            </box>
          </geometry>
          <cast_shadows>1</cast_shadows>
          <transparency>0</transparency>
        </visual>
        <collision name='collision'>
          <pose>0 0 0 0 -0 0</pose>
          <geometry>
            <box>
              <size>2.01142 1 0.568726</size>
            </box>
          </geometry>
          <surface>
            <friction>
              <ode>
                <mu>1</mu>
                <mu2>1</mu2>
                <fdir1>0 0 0</fdir1>
                <slip1>0</slip1>
                <slip2>0</slip2>
              </ode>
            </friction>
            <bounce>
              <restitution_coefficient>0</restitution_coefficient>
              <threshold>1e+06</threshold>
            </bounce>
            <contact>
              <collide_without_contact>0</collide_without_contact>
              <collide_without_contact_bitmask>1</collide_without_contact_bitmask>
              <collide_bitmask>1</collide_bitmask>
              <ode>
                <soft_cfm>0</soft_cfm>
                <soft_erp>0.2</soft_erp>
                <kp>1e+13</kp>
                <kd>1</kd>
                <max_vel>0.01</max_vel>
                <min_depth>0</min_depth>
              </ode>
            </contact>
          </surface>
        </collision>
      </link>
      <link name='left'>
        <pose>0.554283 0.625029 -0.025 1.5707 0 0</pose>
        <inertial>
          <mass>2</mass>
          <inertia>
            <ixx>0.145833</ixx>
            <ixy>0</ixy>
            <ixz>0</ixz>
            <iyy>0.145833</iyy>
            <iyz>0</iyz>
            <izz>0.125</izz>
          </inertia>
          <pose>0 0 0 0 -0 0</pose>
        </inertial>
        <self_collide>0</self_collide>
        <visual name='visual'>
          <pose>0 0 0 0 -0 0</pose>
          <geometry>
            <cylinder>
              <radius>0.3</radius>
              <length>0.25</length>
            </cylinder>
          </geometry>
          <cast_shadows>1</cast_shadows>
          <transparency>0</transparency>
        </visual>
        <collision name='collision'>
          <pose>0 0 0 0 -0 0</pose>
          <geometry>
            <cylinder>
              <radius>0.3</radius>
              <length>0.25</length>
            </cylinder>
          </geometry>
          <surface>
            <friction>
              <ode>
                <mu>1</mu>
                <mu2>1</mu2>
                <fdir1>0 0 0</fdir1>
                <slip1>0</slip1>
                <slip2>0</slip2>
              </ode>
            </friction>
            <bounce>
              <restitution_coefficient>0</restitution_coefficient>
              <threshold>1e+06</threshold>
            </bounce>
            <contact>
              <collide_without_contact>0</collide_without_contact>
              <collide_without_contact_bitmask>1</collide_without_contact_bitmask>
              <collide_bitmask>1</collide_bitmask>
              <ode>
                <soft_cfm>0</soft_cfm>
                <soft_erp>0.2</soft_erp>
                <kp>1e+13</kp>
                <kd>1</kd>
                <max_vel>0.01</max_vel>
                <min_depth>0</min_depth>
              </ode>
            </contact>
          </surface>
        </collision>
      </link>
      <link name='right'>
        <pose>0.554282 -0.625029 -0.025 1.5707 0 0</pose>
        <inertial>
          <mass>2</mass>
          <inertia>
            <ixx>0.145833</ixx>
            <ixy>0</ixy>
            <ixz>0</ixz>
            <iyy>0.145833</iyy>
            <iyz>0</iyz>
            <izz>0.125</izz>
          </inertia>
          <pose>0 0 0 0 -0 0</pose>
        </inertial>
        <self_collide>0</self_collide>
        <visual name='visual'>
          <pose>0 0 0 0 -0 0</pose>
          <geometry>
            <cylinder>
              <radius>0.3</radius>
              <length>0.25</length>
            </cylinder>
          </geometry>
          <cast_shadows>1</cast_shadows>
          <transparency>0</transparency>
        </visual>
        <collision name='collision'>
          <pose>0 0 0 0 -0 0</pose>
          <geometry>
            <cylinder>
              <radius>0.3</radius>
              <length>0.25</length>
            </cylinder>
          </geometry>
          <surface>
            <friction>
              <ode>
                <mu>1</mu>
                <mu2>1</mu2>
                <fdir1>0 0 0</fdir1>
                <slip1>0</slip1>
                <slip2>0</slip2>
              </ode>
            </friction>
            <bounce>
              <restitution_coefficient>0</restitution_coefficient>
              <threshold>1e+06</threshold>
            </bounce>
            <contact>
              <collide_without_contact>0</collide_without_contact>
              <collide_without_contact_bitmask>1</collide_without_contact_bitmask>
              <collide_bitmask>1</collide_bitmask>
              <ode>
                <soft_cfm>0</soft_cfm>
                <soft_erp>0.2</soft_erp>
                <kp>1e+13</kp>
                <kd>1</kd>
                <max_vel>0.01</max_vel>
                <min_depth>0</min_depth>
              </ode>
            </contact>
          </surface>
        </collision>
      </link>
      <link name='caster'>
        <pose>-0.957138 -0 -0.125 0 -0 0</pose>
        <inertial>
          <mass>1</mass>
          <inertia>
            <ixx>0.1</ixx>
            <ixy>0</ixy>
            <ixz>0</ixz>
            <iyy>0.1</iyy>
            <iyz>0</iyz>
            <izz>0.1</izz>
          </inertia>
          <pose>0 0 0 0 -0 0</pose>
        </inertial>
        <self_collide>0</self_collide>
        <visual name='visual'>
          <pose>0 0 0 0 -0 0</pose>
          <geometry>
            <sphere>
              <radius>0.2</radius>
            </sphere>
          </geometry>
          <cast_shadows>1</cast_shadows>
          <transparency>0</transparency>
        </visual>
        <collision name='collision'>
          <pose>0 0 0 0 -0 0</pose>
          <geometry>
            <sphere>
              <radius>0.2</radius>
            </sphere>
          </geometry>
          <surface>
            <friction>
              <ode>
                <mu>1</mu>
                <mu2>1</mu2>
                <fdir1>0 0 0</fdir1>
                <slip1>0</slip1>
                <slip2>0</slip2>
              </ode>
            </friction>
            <bounce>
              <restitution_coefficient>0</restitution_coefficient>
              <threshold>1e+06</threshold>
            </bounce>
            <contact>
              <collide_without_contact>0</collide_without_contact>
              <collide_without_contact_bitmask>1</collide_without_contact_bitmask>
              <collide_bitmask>1</collide_bitmask>
              <ode>
                <soft_cfm>0</soft_cfm>
                <soft_erp>0.2</soft_erp>
                <kp>1e+13</kp>
                <kd>1</kd>
                <max_vel>0.01</max_vel>
                <min_depth>0</min_depth>
              </ode>
            </contact>
          </surface>
        </collision>
      </link>
      <joint name='chassis_left_revolute' type='revolute'>
        <parent>chassis</parent>
        <child>left</child>
        <pose>0 0 0 0 -0 0</pose>
        <axis>
          <xyz>0 0 1</xyz>
          <use_parent_model_frame>0</use_parent_model_frame>
          <limit>
            <lower>-1.79769e+308</lower>
            <upper>1.79769e+308</upper>
            <effort>-1</effort>
            <velocity>-1</velocity>
          </limit>
          <dynamics>
            <spring_reference>0</spring_reference>
            <spring_stiffness>0</spring_stiffness>
            <damping>0</damping>
            <friction>0</friction>
          </dynamics>
        </axis>
        <physics>
          <ode>
            <limit>
              <cfm>0</cfm>
              <erp>0.2</erp>
            </limit>
            <suspension>
              <cfm>0</cfm>
              <erp>0.2</erp>
            </suspension>
          </ode>
        </physics>
      </joint>
      <joint name='chassis_right_revolute' type='revolute'>
        <parent>chassis</parent>
        <child>right</child>
        <pose>0 0 0 0 -0 0</pose>
        <axis>
          <xyz>0 0 1</xyz>
          <use_parent_model_frame>0</use_parent_model_frame>
          <limit>
            <lower>-1.79769e+308</lower>
            <upper>1.79769e+308</upper>
            <effort>-1</effort>
            <velocity>-1</velocity>
          </limit>
          <dynamics>
            <spring_reference>0</spring_reference>
            <spring_stiffness>0</spring_stiffness>
            <damping>0</damping>
            <friction>0</friction>
          </dynamics>
        </axis>
        <physics>
          <ode>
            <limit>
              <cfm>0</cfm>
              <erp>0.2</erp>
            </limit>
            <suspension>
              <cfm>0</cfm>
              <erp>0.2</erp>
            </suspension>
          </ode>
        </physics>
      </joint>
      <joint name='chassis_caster_ball' type='ball'>
        <parent>chassis</parent>
        <child>caster</child>
        <pose>0 0 0 0 -0 0</pose>
        <physics>
          <ode>
            <limit>
              <cfm>0</cfm>
              <erp>0.2</erp>
            </limit>
            <suspension>
              <cfm>0</cfm>
              <erp>0.2</erp>
            </suspension>
          </ode>
        </physics>
      </joint>
      <static>0</static>
      <allow_auto_disable>1</allow_auto_disable>
    </model>




    <state world_name='default'>
      <sim_time>0 0</sim_time>
      <real_time>0 0</real_time>
      <wall_time>1635032891 594629124</wall_time>
      <iterations>0</iterations>

      <model name='ground_plane'>
        <pose>0 0 0 0 -0 0</pose>
        <scale>1 1 1</scale>
        <link name='link'>
          <pose>0 0 0 0 -0 0</pose>
          <velocity>0 0 0 0 -0 0</velocity>
          <acceleration>nan nan nan nan nan nan</acceleration>
          <wrench>0 0 0 0 -0 0</wrench>
        </link>
      </model>
      <light name='sun'>
        <pose>0 0 10 0 -0 0</pose>
      </light>
    </state>
    <gui fullscreen='0'>
      <camera name='user_camera'>
        <pose>0.195264 0.153042 0.144258 -0 0.483643 -2.61499</pose>
        <view_controller>orbit</view_controller>
        <projection_type>perspective</projection_type>
      </camera>
    </gui>
  </world>
</sdf>
